Workbook

Sheet BAŞLANGIÇ
A1: TÜRKİYE YEŞİL TAKSONOMİSİ | ŞİRKET KONTROL VE ÖN DEĞERLENDİRME ARACI
A3: 16 Sektör | 137 Ekonomik Faaliyet
A5: 1. Şirketinizin ana faaliyetini yazın.
A6: 2. Sektörünüzü seçin.
A7: 3. Faaliyet listenizde eşleşen ekonomik faaliyeti bulun.
A8: 4. İlgili çevresel hedefleri ve hazırlık alanlarını inceleyin.
A9: 5. Eksik veri ve belgelerinizi belirleyin.
A12: ÖNEMLİ: Bu Excel hukuki uygunluk veya resmi taksonomi doğrulaması değildir. Bir faaliyetin EK-1’de yer alması, faaliyetin otomatik olarak Türkiye Yeşil Taksonomisine Uyumlu olduğu anlamına gelmez. Uyumluluk değerlendirmesi; ilgili teknik tarama kriterleri, önemli katkı, önemli zarar vermeme ve asgari sosyal koruma şartlarının birlikte değerlendirilmesini gerektirir.
A19: TEMEL AYRIM UYGUN EKONOMİK FAALİYET: EK-1 kapsamında değerlendirmeye girebilen faaliyet. TAKSONOMİYE UYUMLU EKONOMİK FAALİYET: Teknik tarama kriterleri + önemli katkı + DNSH + asgari sosyal koruma şartlarını birlikte sağlayan faaliyet.

Sheet DASHBOARD
A1: TÜRKİYE YEŞİL TAKSONOMİSİ | ŞİRKET HAZIRLIK DASHBOARD
N2: Faaliyet Türü | O2: Sayı
A3: Toplam sektör | D3: Toplam ekonomik faaliyet | G3: Şirketimin eşleşen faaliyet sayısı | J3: İncelenen faaliyet | N3: Kolaylaştırıcı Faaliyet | O3: =COUNTIF('137 EKONOMİK FAALİYET'!H3:H139,N3) | Q3: Sera gazı emisyonlarının azaltımı | R3: =COUNTIF('137 EKONOMİK FAALİYET'!K3:K139,"Evet")
A4: =COUNTA('16 SEKTÖR'!B3:B18) | D4: =COUNTA('137 EKONOMİK FAALİYET'!E3:E139) | G4: =IF('ŞİRKETİMİ KONTROL ET'!B4="",0,COUNTIF('137 EKONOMİK FAALİYET'!C3:C139,'ŞİRKETİMİ KONTROL ET'!B4)) | J4: =IF('ŞİRKETİMİ KONTROL ET'!B5="",0,1) | N4: Geçiş Faaliyeti | O4: =COUNTIF('137 EKONOMİK FAALİYET'!H3:H139,N4) | Q4: İklim değişikliğine uyum | R4: =COUNTIF('137 EKONOMİK FAALİYET'!L3:L139,"Evet")
N5: Diğer / Genel Faaliyet | O5: =COUNTIF('137 EKONOMİK FAALİYET'!H3:H139,N5) | Q5: Su ve deniz kaynaklarının sürdürülebilir kullanımı ve korunması | R5: =COUNTIF('137 EKONOMİK FAALİYET'!M3:M139,"Evet")
N6: Kolaylaştırıcı / Geçiş | O6: =COUNTIF('137 EKONOMİK FAALİYET'!H3:H139,N6) | Q6: Döngüsel ekonomiye geçiş | R6: =COUNTIF('137 EKONOMİK FAALİYET'!N3:N139,"Evet")
A7: Hazırlık KPI | B7: Değer | D7: Ön değerlendirme durumu | E7: ='ŞİRKETİMİ KONTROL ET'!F13 | Q7: Kirliliğin önlenmesi ve kontrolü | R7: =COUNTIF('137 EKONOMİK FAALİYET'!O3:O139,"Evet")
A8: Verisi tamamlanan alan | B8: =COUNTIF('HAZIRLIK CHECKLIST'!C3:C23,"Tamamlandı")/COUNTA('HAZIRLIK CHECKLIST'!B3:B23) | Q8: Biyoçeşitliliğin ve ekosistemlerin korunması ile restorasyonu | R8: =COUNTIF('137 EKONOMİK FAALİYET'!P3:P139,"Evet")
A9: Eksik veri | B9: =COUNTIF('HAZIRLIK CHECKLIST'!C3:C23,"Eksik")/COUNTA('HAZIRLIK CHECKLIST'!B3:B23) | N9: Durum | O9: Sayı
A10: Eksik belge | B10: =COUNTIF('KANIT BELGE ENVANTERİ'!I3:I32,"Eksik")/COUNTA('KANIT BELGE ENVANTERİ'!I3:I32) | N10: Tamamlandı | O10: =COUNTIF('HAZIRLIK CHECKLIST'!C3:C23,N10)
N11: İnceleniyor | O11: =COUNTIF('HAZIRLIK CHECKLIST'!C3:C23,N11)
N12: Eksik | O12: =COUNTIF('HAZIRLIK CHECKLIST'!C3:C23,N12)
N13: Uygulanamaz | O13: =COUNTIF('HAZIRLIK CHECKLIST'!C3:C23,N13)

Sheet 137 EKONOMİK FAALİYET
A1: 137 EKONOMİK FAALİYET | NİHAİ EK-1 ANA VERİ TABLOSU
A2: Sıra No | B2: Sektör No | C2: Sektör | D2: Faaliyet Kodu | E2: Ekonomik Faaliyet Adı | F2: Ekonomik Faaliyet Tanımı | G2: NACE Kodu / Kodları (resmi kaynakta varsa) | H2: Faaliyet Türü | I2: Kolaylaştırıcı Faaliyet | J2: Geçiş Faaliyeti | K2: Sera gazı emisyonlarının azaltımı | L2: İklim değişikliğine uyum | M2: Su ve deniz kaynaklarının sürdürülebilir kullanımı ve korunması | N2: Döngüsel ekonomiye geçiş | O2: Kirliliğin önlenmesi ve kontrolü | P2: Biyoçeşitliliğin ve ekosistemlerin korunması ile restorasyonu | Q2: Teknik Tarama Kriteri Mevcut mu? | R2: Şirket İçin Temel Veri İhtiyacı | S2: Muhtemel Kanıt / Belge | T2: Açıklama | U2: Kaynak
A3: 1 | B3: 1 | C3: Ormancılık Faaliyetleri | D3: A-1.1; B-1.1 | E3: Ağaçlandırma | F3: EK-1 faaliyet başlığıdır. Ayrıntılı kapsam ve eşikler için yayımlanacak resmi teknik tarama kriterleri incelenmelidir. | H3: Diğer / Genel Faaliyet | I3: Hayır | J3: Hayır | K3: Evet | L3: Evet | Q3: Yayımlanmamış / Doğrulanmalı | R3: Faaliyet hacmi; enerji, yakıt, su, atık ve sera gazı verileri; hasılat, CAPEX ve OPEX; teknik performans göstergeleri. | S3: İzin ve ruhsatlar; sayaç/fatura kayıtları; emisyon ve atık beyanları; proje/teknik raporlar; doğrulama ve sosyal koruma belgeleri. | T3: NACE kodu eşleştirmeyi destekler; tek başına taksonomi uyumluluğunu kanıtlamaz. | U3: Türkiye Yeşil Taksonomisi Yönetmeliği, EK-1
A4: 2 | B4: 1 | C4: Ormancılık Faaliyetleri | D4: A-1.2; B-1.2 | E4: Yeniden Ağaçlandırma, Doğal Orman Yenilenmesi, Ormanların Rehabilitasyonu ve Restorasyonu | F4: EK-1 faaliyet başlığıdır. Ayrıntılı kapsam ve eşikler için yayımlanacak resmi teknik tarama kriterleri incelenmelidir. | H4: Diğer / Genel Faaliyet | I4: Hayır | J4: Hayır | K4: Evet | L4: Evet | Q4: Yayımlanmamış / Doğrulanmalı | R4: Faaliyet hacmi; enerji, yakıt, su, atık ve sera gazı verileri; hasılat, CAPEX ve OPEX; teknik performans göstergeleri. | S4: İzin ve ruhsatlar; sayaç/fatura kayıtları; emisyon ve atık beyanları; proje/teknik raporlar; doğrulama ve sosyal koruma belgeleri. | T4: NACE kodu eşleştirmeyi destekler; tek başına taksonomi uyumluluğunu kanıtlamaz. | U4: Türkiye Yeşil Taksonomisi Yönetmeliği, EK-1
A5: 3 | B5: 1 | C5: Ormancılık Faaliyetleri | D5: A-1.3; B-1.3 | E5: Orman Yönetimi | F5: EK-1 faaliyet başlığıdır. Ayrıntılı kapsam ve eşikler için yayımlanacak resmi teknik tarama kriterleri incelenmelidir. | H5: Diğer / Genel Faaliyet | I5: Hayır | J5: Hayır | K5: Evet | L5: Evet | Q5: Yayımlanmamış / Doğrulanmalı | R5: Faaliyet hacmi; enerji, yakıt, su, atık ve sera gazı verileri; hasılat, CAPEX ve OPEX; teknik performans göstergeleri. | S5: İzin ve ruhsatlar; sayaç/fatura kayıtları; emisyon ve atık beyanları; proje/teknik raporlar; doğrulama ve sosyal koruma belgeleri. | T5: NACE kodu eşleştirmeyi destekler; tek başına taksonomi uyumluluğunu kanıtlamaz. | U5: Türkiye Yeşil Taksonomisi Yönetmeliği, EK-1
A6: 4 | B6: 1 | C6: Ormancılık Faaliyetleri | D6: A-1.4; B-1.4 | E6: Koruma Ormancılığı | F6: EK-1 faaliyet başlığıdır. Ayrıntılı kapsam ve eşikler için yayımlanacak resmi teknik tarama kriterleri incelenmelidir. | H6: Diğer / Genel Faaliyet | I6: Hayır | J6: Hayır | K6: Evet | L6: Evet | Q6: Yayımlanmamış / Doğrulanmalı | R6: Faaliyet hacmi; enerji, yakıt, su, atık ve sera gazı verileri; hasılat, CAPEX ve OPEX; teknik performans göstergeleri. | S6: İzin ve ruhsatlar; sayaç/fatura kayıtları; emisyon ve atık beyanları; proje/teknik raporlar; doğrulama ve sosyal koruma belgeleri. | T6: NACE kodu eşleştirmeyi destekler; tek başına taksonomi uyumluluğunu kanıtlamaz. | U6: Türkiye Yeşil Taksonomisi Yönetmeliği, EK-1
A7: 5 | B7: 2 | C7: Çevre Koruma ve Restorasyon Faaliyetleri | D7: A-2.1; B-2.1 | E7: Sulak Alanların Restorasyonu | F7: EK-1 faaliyet başlığıdır. Ayrıntılı kapsam ve eşikler için yayımlanacak resmi teknik tarama kriterleri incelenmelidir. | H7: Diğer / Genel Faaliyet | I7: Hayır | J7: Hayır | K7: Evet | L7: Evet | Q7: Yayımlanmamış / Doğrulanmalı | R7: Faaliyet hacmi; enerji, yakıt, su, atık ve sera gazı verileri; hasılat, CAPEX ve OPEX; teknik performans göstergeleri. | S7: İzin ve ruhsatlar; sayaç/fatura kayıtları; emisyon ve atık beyanları; proje/teknik raporlar; doğrulama ve sosyal koruma belgeleri. | T7: NACE kodu eşleştirmeyi destekler; tek başına taksonomi uyumluluğunu kanıtlamaz. | U7: Türkiye Yeşil Taksonomisi Yönetmeliği, EK-1
A8: 6 | B8: 3 | C8: İmalat Faaliyetleri | D8: A-3.1; B-3.1 | E8: Yenilenebilir Enerji Teknolojilerinin İmalatı (Kolaylaştırıcı Faaliyet) | F8: EK-1 faaliyet başlığıdır. Ayrıntılı kapsam ve eşikler için yayımlanacak resmi teknik tarama kriterleri incelenmelidir. | H8: Kolaylaştırıcı Faaliyet | I8: Evet | J8: Hayır | K8: Evet | L8: Evet | Q8: Yayımlanmamış / Doğrulanmalı | R8: Faaliyet hacmi; enerji, yakıt, su, atık ve sera gazı verileri; hasılat, CAPEX ve OPEX; teknik performans göstergeleri. | S8: İzin ve ruhsatlar; sayaç/fatura kayıtları; emisyon ve atık beyanları; proje/teknik raporlar; doğrulama ve sosyal koruma belgeleri. | T8: NACE kodu eşleştirmeyi destekler; tek başına taksonomi uyumluluğunu kanıtlamaz. | U8: Türkiye Yeşil Taksonomisi Yönetmeliği, EK-1
A9: 7 | B9: 3 | C9: İmalat Faaliyetleri | D9: A-3.2; B-3.2 | E9: Hidrojen İmalatı ve Kullanımına Yönelik Ekipmanların İmalatı (Kolaylaştırıcı Faaliyet) | F9: EK-1 faaliyet başlığıdır. Ayrıntılı kapsam ve eşikler için yayımlanacak resmi teknik tarama kriterleri incelenmelidir. | H9: Kolaylaştırıcı Faaliyet | I9: Evet | J9: Hayır | K9: Evet | L9: Evet | Q9: Yayımlanmamış / Doğrulanmalı | R9: Faaliyet hacmi; enerji, yakıt, su, atık ve sera gazı verileri; hasılat, CAPEX ve OPEX; teknik performans göstergeleri. | S9: İzin ve ruhsatlar; sayaç/fatura kayıtları; emisyon ve atık beyanları; proje/teknik raporlar; doğrulama ve sosyal koruma belgeleri. | T9: NACE kodu eşleştirmeyi destekler; tek başına taksonomi uyumluluğunu kanıtlamaz. | U9: Türkiye Yeşil Taksonomisi Yönetmeliği, EK-1
A10: 8 | B10: 3 | C10: İmalat Faaliyetleri | D10: A-3.3; B-3.3 | E10: Taşımacılık İçin Düşük Karbon Teknolojilerinin İmalatı (Kolaylaştırıcı Faaliyet) | F10: EK-1 faaliyet başlığıdır. Ayrıntılı kapsam ve eşikler için yayımlanacak resmi teknik tarama kriterleri incelenmelidir. | H10: Kolaylaştırıcı Faaliyet | I10: Evet | J10: Hayır | K10: Evet | L10: Evet | Q10: Yayımlanmamış / Doğrulanmalı | R10: Faaliyet hacmi; enerji, yakıt, su, atık ve sera gazı verileri; hasılat, CAPEX ve OPEX; teknik performans göstergeleri. | S10: İzin ve ruhsatlar; sayaç/fatura kayıtları; emisyon ve atık beyanları; proje/teknik raporlar; doğrulama ve sosyal koruma belgeleri. | T10: NACE kodu eşleştirmeyi destekler; tek başına taksonomi uyumluluğunu kanıtlamaz. | U10: Türkiye Yeşil Taksonomisi Yönetmeliği, EK-1
A11: 9 | B11: 3 | C11: İmalat Faaliyetleri | D11: A-3.4; B-3.4 | E11: Batarya İmalatı (Kolaylaştırıcı Faaliyet) | F11: EK-1 faaliyet başlığıdır. Ayrıntılı kapsam ve eşikler için yayımlanacak resmi teknik tarama kriterleri incelenmelidir. | H11: Kolaylaştırıcı Faaliyet | I11: Evet | J11: Hayır | K11: Evet | L11: Evet | Q11: Yayımlanmamış / Doğrulanmalı | R11: Faaliyet hacmi; enerji, yakıt, su, atık ve sera gazı verileri; hasılat, CAPEX ve OPEX; teknik performans göstergeleri. | S11: İzin ve ruhsatlar; sayaç/fatura kayıtları; emisyon ve atık beyanları; proje/teknik raporlar; doğrulama ve sosyal koruma belgeleri. | T11: NACE kodu eşleştirmeyi destekler; tek başına taksonomi uyumluluğunu kanıtlamaz. | U11: Türkiye Yeşil Taksonomisi Yönetmeliği, EK-1
A12: 10 | B12: 3 | C12: İmalat Faaliyetleri | D12: A-3.5; B-3.5 | E12: Binalar İçin Enerji Verimliliği Ekipmanlarının İmalatı (Kolaylaştırıcı Faaliyet) | F12: EK-1 faaliyet başlığıdır. Ayrıntılı kapsam ve eşikler için yayımlanacak resmi teknik tarama kriterleri incelenmelidir. | H12: Kolaylaştırıcı Faaliyet | I12: Evet | J12: Hayır | K12: Evet | L12: Evet | Q12: Yayımlanmamış / Doğrulanmalı | R12: Faaliyet hacmi; enerji, yakıt, su, atık ve sera gazı verileri; hasılat, CAPEX ve OPEX; teknik performans göstergeleri. | S12: İzin ve ruhsatlar; sayaç/fatura kayıtları; emisyon ve atık beyanları; proje/teknik raporlar; doğrulama ve sosyal koruma belgeleri. | T12: NACE kodu eşleştirmeyi destekler; tek başına taksonomi uyumluluğunu kanıtlamaz. | U12: Türkiye Yeşil Taksonomisi Yönetmeliği, EK-1
A13: 11 | B13: 3 | C13: İmalat Faaliyetleri | D13: A-3.6; B-3.6 | E13: Diğer Düşük Karbon Teknolojilerinin İmalatı (Kolaylaştırıcı Faaliyet) | F13: EK-1 faaliyet başlığıdır. Ayrıntılı kapsam ve eşikler için yayımlanacak resmi teknik tarama kriterleri incelenmelidir. | H13: Kolaylaştırıcı Faaliyet | I13: Evet | J13: Hayır | K13: Evet | L13: Evet | Q13: Yayımlanmamış / Doğrulanmalı | R13: Faaliyet hacmi; enerji, yakıt, su, atık ve sera gazı verileri; hasılat, CAPEX ve OPEX; teknik performans göstergeleri. | S13: İzin ve ruhsatlar; sayaç/fatura kayıtları; emisyon ve atık beyanları; proje/teknik raporlar; doğrulama ve sosyal koruma belgeleri. | T13: NACE kodu eşleştirmeyi destekler; tek başına taksonomi uyumluluğunu kanıtlamaz. | U13: Türkiye Yeşil Taksonomisi Yönetmeliği, EK-1
A14: 12 | B14: 3 | C14: İmalat Faaliyetleri | D14: A-3.7; B-3.7 | E14: Çimento İmalatı | F14: EK-1 faaliyet başlığıdır. Ayrıntılı kapsam ve eşikler için yayımlanacak resmi teknik tarama kriterleri incelenmelidir. | H14: Geçiş Faaliyeti | I14: Hayır | J14: Evet | K14: Evet | L14: Evet | Q14: Yayımlanmamış / Doğrulanmalı | R14: Faaliyet hacmi; enerji, yakıt, su, atık ve sera gazı verileri; hasılat, CAPEX ve OPEX; teknik performans göstergeleri. | S14: İzin ve ruhsatlar; sayaç/fatura kayıtları; emisyon ve atık beyanları; proje/teknik raporlar; doğrulama ve sosyal koruma belgeleri. | T14: NACE kodu eşleştirmeyi destekler; tek başına taksonomi uyumluluğunu kanıtlamaz. | U14: Türkiye Yeşil Taksonomisi Yönetmeliği, EK-1
... A81: 79 | B81: 6 | C81: Ulaştırma Faaliyetleri | D81: A-6.14; B-6.14 | E81: Demiryolu Taşımacılığı Altyapısı | F81: EK-1 faaliyet başlığıdır. Ayrıntılı kapsam ve eşikler için yayımlanacak resmi teknik tarama kriterleri incelenmelidir. | H81: Kolaylaştırıcı Faaliyet | I81: Evet | J81: Hayır | K81: Evet | L81: Evet | Q81: Yayımlanmamış / Doğrulanmalı | R81: Faaliyet hacmi; enerji, yakıt, su, atık ve sera gazı verileri; hasılat, CAPEX ve OPEX; teknik performans göstergeleri. | S81: İzin ve ruhsatlar; sayaç/fatura kayıtları; emisyon ve atık beyanları; proje/teknik raporlar; doğrulama ve sosyal koruma belgeleri. | T81: NACE kodu eşleştirmeyi destekler; tek başına taksonomi uyumluluğunu kanıtlamaz. | U81: Türkiye Yeşil Taksonomisi Yönetmeliği, EK-1
A82: 80 | B82: 6 | C82: Ulaştırma Faaliyetleri | D82: A-6.15 | E82: Düşük Karbonlu Karayolu Taşımacılığı ve Toplu Taşımaya Olanak Sağlayan Altyapı | F82: EK-1 faaliyet başlığıdır. Ayrıntılı kapsam ve eşikler için yayımlanacak resmi teknik tarama kriterleri incelenmelidir. | H82: Kolaylaştırıcı Faaliyet | I82: Evet | J82: Hayır | K82: Evet | Q82: Yayımlanmamış / Doğrulanmalı | R82: Faaliyet hacmi; enerji, yakıt, su, atık ve sera gazı verileri; hasılat, CAPEX ve OPEX; teknik performans göstergeleri. | S82: İzin ve ruhsatlar; sayaç/fatura kayıtları; emisyon ve atık beyanları; proje/teknik raporlar; doğrulama ve sosyal koruma belgeleri. | T82: NACE kodu eşleştirmeyi destekler; tek başına taksonomi uyumluluğunu kanıtlamaz. | U82: Türkiye Yeşil Taksonomisi Yönetmeliği, EK-1
A83: 81 | B83: 6 | C83: Ulaştırma Faaliyetleri | D83: A-6.16 | E83: Düşük Karbonlu Su Taşımacılığına Olanak Sağlayan Altyapı | F83: EK-1 faaliyet başlığıdır. Ayrıntılı kapsam ve eşikler için yayımlanacak resmi teknik tarama kriterleri incelenmelidir. | H83: Kolaylaştırıcı Faaliyet | I83: Evet | J83: Hayır | K83: Evet | Q83: Yayımlanmamış / Doğrulanmalı | R83: Faaliyet hacmi; enerji, yakıt, su, atık ve sera gazı verileri; hasılat, CAPEX ve OPEX; teknik performans göstergeleri. | S83: İzin ve ruhsatlar; sayaç/fatura kayıtları; emisyon ve atık beyanları; proje/teknik raporlar; doğrulama ve sosyal koruma belgeleri. | T83: NACE kodu eşleştirmeyi destekler; tek başına taksonomi uyumluluğunu kanıtlamaz. | U83: Türkiye Yeşil Taksonomisi Yönetmeliği, EK-1
A84: 82 | B84: 6 | C84: Ulaştırma Faaliyetleri | D84: A-6.17 | E84: Düşük Karbonlu Havalimanı Altyapısı | F84: EK-1 faaliyet başlığıdır. Ayrıntılı kapsam ve eşikler için yayımlanacak resmi teknik tarama kriterleri incelenmelidir. | H84: Kolaylaştırıcı Faaliyet | I84: Evet | J84: Hayır | K84: Evet | Q84: Yayımlanmamış / Doğrulanmalı | R84: Faaliyet hacmi; enerji, yakıt, su, atık ve sera gazı verileri; hasılat, CAPEX ve OPEX; teknik performans göstergeleri. | S84: İzin ve ruhsatlar; sayaç/fatura kayıtları; emisyon ve atık beyanları; proje/teknik raporlar; doğrulama ve sosyal koruma belgeleri. | T84: NACE kodu eşleştirmeyi destekler; tek başına taksonomi uyumluluğunu kanıtlamaz. | U84: Türkiye Yeşil Taksonomisi Yönetmeliği, EK-1
A85: 83 | B85: 7 | C85: İnşaat ve Emlak Faaliyetleri | D85: A-7.1; B-7.1; Ç-3.1 | E85: Yeni Binaların İnşası | F85: EK-1 faaliyet başlığıdır. Ayrıntılı kapsam ve eşikler için yayımlanacak resmi teknik tarama kriterleri incelenmelidir. | H85: Diğer / Genel Faaliyet | I85: Hayır | J85: Hayır | K85: Evet | L85: Evet | N85: Evet | Q85: Yayımlanmamış / Doğrulanmalı | R85: Faaliyet hacmi; enerji, yakıt, su, atık ve sera gazı verileri; hasılat, CAPEX ve OPEX; teknik performans göstergeleri. | S85: İzin ve ruhsatlar; sayaç/fatura kayıtları; emisyon ve atık beyanları; proje/teknik raporlar; doğrulama ve sosyal koruma belgeleri. | T85: NACE kodu eşleştirmeyi destekler; tek başına taksonomi uyumluluğunu kanıtlamaz. | U85: Türkiye Yeşil Taksonomisi Yönetmeliği, EK-1
A86: 84 | B86: 7 | C86: İnşaat ve Emlak Faaliyetleri | D86: A-7.2; B-7.2; Ç-3.2 | E86: Mevcut Binaların Yenilenmesi | F86: EK-1 faaliyet başlığıdır. Ayrıntılı kapsam ve eşikler için yayımlanacak resmi teknik tarama kriterleri incelenmelidir. | H86: Geçiş Faaliyeti | I86: Hayır | J86: Evet | K86: Evet | L86: Evet | N86: Evet | Q86: Yayımlanmamış / Doğrulanmalı | R86: Faaliyet hacmi; enerji, yakıt, su, atık ve sera gazı verileri; hasılat, CAPEX ve OPEX; teknik performans göstergeleri. | S86: İzin ve ruhsatlar; sayaç/fatura kayıtları; emisyon ve atık beyanları; proje/teknik raporlar; doğrulama ve sosyal koruma belgeleri. | T86: NACE kodu eşleştirmeyi destekler; tek başına taksonomi uyumluluğunu kanıtlamaz. | U86: Türkiye Yeşil Taksonomisi Yönetmeliği, EK-1
A87: 85 | B87: 7 | C87: İnşaat ve Emlak Faaliyetleri | D87: A-7.3; B-7.3 | E87: Enerji Verimliliği Ekipmanlarının Kurulumu, Bakımı ve Onarımı | F87: EK-1 faaliyet başlığıdır. Ayrıntılı kapsam ve eşikler için yayımlanacak resmi teknik tarama kriterleri incelenmelidir. | H87: Kolaylaştırıcı Faaliyet | I87: Evet | J87: Hayır | K87: Evet | L87: Evet | Q87: Yayımlanmamış / Doğrulanmalı | R87: Faaliyet hacmi; enerji, yakıt, su, atık ve sera gazı verileri; hasılat, CAPEX ve OPEX; teknik performans göstergeleri. | S87: İzin ve ruhsatlar; sayaç/fatura kayıtları; emisyon ve atık beyanları; proje/teknik raporlar; doğrulama ve sosyal koruma belgeleri. | T87: NACE kodu eşleştirmeyi destekler; tek başına taksonomi uyumluluğunu kanıtlamaz. | U87: Türkiye Yeşil Taksonomisi Yönetmeliği, EK-1
A88: 86 | B88: 7 | C88: İnşaat ve Emlak Faaliyetleri | D88: A-7.4; B-7.4 | E88: Binalarda ve Binalara Bağlı Park Yerlerinde Elektrikli Araçlar İçin Şarj İstasyonlarının Kurulumu, Bakımı ve Onarımı | F88: EK-1 faaliyet başlığıdır. Ayrıntılı kapsam ve eşikler için yayımlanacak resmi teknik tarama kriterleri incelenmelidir. | H88: Kolaylaştırıcı Faaliyet | I88: Evet | J88: Hayır | K88: Evet | L88: Evet | Q88: Yayımlanmamış / Doğrulanmalı | R88: Faaliyet hacmi; enerji, yakıt, su, atık ve sera gazı verileri; hasılat, CAPEX ve OPEX; teknik performans göstergeleri. | S88: İzin ve ruhsatlar; sayaç/fatura kayıtları; emisyon ve atık beyanları; proje/teknik raporlar; doğrulama ve sosyal koruma belgeleri. | T88: NACE kodu eşleştirmeyi destekler; tek başına taksonomi uyumluluğunu kanıtlamaz. | U88: Türkiye Yeşil Taksonomisi Yönetmeliği, EK-1
A89: 87 | B89: 7 | C89: İnşaat ve Emlak Faaliyetleri | D89: A-7.5; B-7.5 | E89: Binaların Enerji Performansını Ölçmek, Düzenlemek ve Kontrol Etmek İçin Kullanılan Alet ve Cihazların Kurulumu, Bakımı ve Onarımı | F89: EK-1 faaliyet başlığıdır. Ayrıntılı kapsam ve eşikler için yayımlanacak resmi teknik tarama kriterleri incelenmelidir. | H89: Kolaylaştırıcı Faaliyet | I89: Evet | J89: Hayır | K89: Evet | L89: Evet | Q89: Yayımlanmamış / Doğrulanmalı | R89: Faaliyet hacmi; enerji, yakıt, su, atık ve sera gazı verileri; hasılat, CAPEX ve OPEX; teknik performans göstergeleri. | S89: İzin ve ruhsatlar; sayaç/fatura kayıtları; emisyon ve atık beyanları; proje/teknik raporlar; doğrulama ve sosyal koruma belgeleri. | T89: NACE kodu eşleştirmeyi destekler; tek başına taksonomi uyumluluğunu kanıtlamaz. | U89: Türkiye Yeşil Taksonomisi Yönetmeliği, EK-1
A90: 88 | B90: 7 | C90: İnşaat ve Emlak Faaliyetleri | D90: A-7.6; B-7.6 | E90: Yenilenebilir Enerji Teknolojilerinin Kurulumu, Bakımı ve Onarımı | F90: EK-1 faaliyet başlığıdır. Ayrıntılı kapsam ve eşikler için yayımlanacak resmi teknik tarama kriterleri incelenmelidir. | H90: Kolaylaştırıcı Faaliyet | I90: Evet | J90: Hayır | K90: Evet | L90: Evet | Q90: Yayımlanmamış / Doğrulanmalı | R90: Faaliyet hacmi; enerji, yakıt, su, atık ve sera gazı verileri; hasılat, CAPEX ve OPEX; teknik performans göstergeleri. | S90: İzin ve ruhsatlar; sayaç/fatura kayıtları; emisyon ve atık beyanları; proje/teknik raporlar; doğrulama ve sosyal koruma belgeleri. | T90: NACE kodu eşleştirmeyi destekler; tek başına taksonomi uyumluluğunu kanıtlamaz. | U90: Türkiye Yeşil Taksonomisi Yönetmeliği, EK-1
A91: 89 | B91: 7 | C91: İnşaat ve Emlak Faaliyetleri | D91: A-7.7; B-7.7 | E91: Binaların Satın Alınması ve Mülkiyeti | F91: EK-1 faaliyet başlığıdır. Ayrıntılı kapsam ve eşikler için yayımlanacak resmi teknik tarama kriterleri incelenmelidir. | H91: Diğer / Genel Faaliyet | I91: Hayır | J91: Hayır | K91: Evet | L91: Evet | Q91: Yayımlanmamış / Doğrulanmalı | R91: Faaliyet hacmi; enerji, yakıt, su, atık ve sera gazı verileri; hasılat, CAPEX ve OPEX; teknik performans göstergeleri. | S91: İzin ve ruhsatlar; sayaç/fatura kayıtları; emisyon ve atık beyanları; proje/teknik raporlar; doğrulama ve sosyal koruma belgeleri. | T91: NACE kodu eşleştirmeyi destekler; tek başına taksonomi uyumluluğunu kanıtlamaz. | U91: Türkiye Yeşil Taksonomisi Yönetmeliği, EK-1
A92: 90 | B92: 8 | C92: Bilgi ve İletişim Faaliyetleri | D92: A-8.1; B-8.1 | E92: Veri İşleme, Barındırma ve İlgili Faaliyetler | F92: EK-1 faaliyet başlığıdır. Ayrıntılı kapsam ve eşikler için yayımlanacak resmi teknik tarama kriterleri incelenmelidir. | H92: Geçiş Faaliyeti | I92: Hayır | J92: Evet | K92: Evet | L92: Evet | Q92: Yayımlanmamış / Doğrulanmalı | R92: Faaliyet hacmi; enerji, yakıt, su, atık ve sera gazı verileri; hasılat, CAPEX ve OPEX; teknik performans göstergeleri. | S92: İzin ve ruhsatlar; sayaç/fatura kayıtları; emisyon ve atık beyanları; proje/teknik raporlar; doğrulama ve sosyal koruma belgeleri. | T92: NACE kodu eşleştirmeyi destekler; tek başına taksonomi uyumluluğunu kanıtlamaz. | U92: Türkiye Yeşil Taksonomisi Yönetmeliği, EK-1
A93: 91 | B93: 8 | C93: Bilgi ve İletişim Faaliyetleri | D93: A-8.2; B-8.2 | E93: Sera Gazı Emisyonlarının Azaltılması İçin Veriye Dayalı Çözümler | F93: EK-1 faaliyet başlığıdır. Ayrıntılı kapsam ve eşikler için yayımlanacak resmi teknik tarama kriterleri incelenmelidir. | H93: Kolaylaştırıcı Faaliyet | I93: Evet | J93: Hayır | K93: Evet | L93: Evet | Q93: Yayımlanmamış / Doğrulanmalı | R93: Faaliyet hacmi; enerji, yakıt, su, atık ve sera gazı verileri; hasılat, CAPEX ve OPEX; teknik performans göstergeleri. | S93: İzin ve ruhsatlar; sayaç/fatura kayıtları; emisyon ve atık beyanları; proje/teknik raporlar; doğrulama ve sosyal koruma belgeleri. | T93: NACE kodu eşleştirmeyi destekler; tek başına taksonomi uyumluluğunu kanıtlamaz. | U93: Türkiye Yeşil Taksonomisi Yönetmeliği, EK-1
A94: 92 | B94: 9 | C94: Mesleki, Bilimsel ve Teknik Faaliyetler | D94: A-9.1; B-9.1 | E94: Pazar Araştırması, Geliştirme ve İnovasyona Yakın | F94: EK-1 faaliyet başlığıdır. Ayrıntılı kapsam ve eşikler için yayımlanacak resmi teknik tarama kriterleri incelenmelidir. | H94: Kolaylaştırıcı Faaliyet | I94: Evet | J94: Hayır | K94: Evet | L94: Evet | Q94: Yayımlanmamış / Doğrulanmalı | R94: Faaliyet hacmi; enerji, yakıt, su, atık ve sera gazı verileri; hasılat, CAPEX ve OPEX; teknik performans göstergeleri. | S94: İzin ve ruhsatlar; sayaç/fatura kayıtları; emisyon ve atık beyanları; proje/teknik raporlar; doğrulama ve sosyal koruma belgeleri. | T94: NACE kodu eşleştirmeyi destekler; tek başına taksonomi uyumluluğunu kanıtlamaz. | U94: Türkiye Yeşil Taksonomisi Yönetmeliği, EK-1
A95: 93 | B95: 9 | C95: Mesleki, Bilimsel ve Teknik Faaliyetler | D95: A-9.2; B-9.2 | E95: Karbondioksitin Doğrudan Havadan Yakalanması İçin Araştırma, Geliştirme ve İnovasyon | F95: EK-1 faaliyet başlığıdır. Ayrıntılı kapsam ve eşikler için yayımlanacak resmi teknik tarama kriterleri incelenmelidir. | H95: Kolaylaştırıcı Faaliyet | I95: Evet | J95: Hayır | K95: Evet | L95: Evet | Q95: Yayımlanmamış / Doğrulanmalı | R95: Faaliyet hacmi; enerji, yakıt, su, atık ve sera gazı verileri; hasılat, CAPEX ve OPEX; teknik performans göstergeleri. | S95: İzin ve ruhsatlar; sayaç/fatura kayıtları; emisyon ve atık beyanları; proje/teknik raporlar; doğrulama ve sosyal koruma belgeleri. | T95: NACE kodu eşleştirmeyi destekler; tek başına taksonomi uyumluluğunu kanıtlamaz. | U95: Türkiye Yeşil Taksonomisi Yönetmeliği, EK-1
A96: 94 | B96: 9 | C96: Mesleki, Bilimsel ve Teknik Faaliyetler | D96: A-9.3; B-9.3 | E96: Binaların Enerji Performansı İle İlgili Profesyonel Hizmetler | F96: EK-1 faaliyet başlığıdır. Ayrıntılı kapsam ve eşikler için yayımlanacak resmi teknik tarama kriterleri incelenmelidir. | H96: Kolaylaştırıcı Faaliyet | I96: Evet | J96: Hayır | K96: Evet | L96: Evet | Q96: Yayımlanmamış / Doğrulanmalı | R96: Faaliyet hacmi; enerji, yakıt, su, atık ve sera gazı verileri; hasılat, CAPEX ve OPEX; teknik performans göstergeleri. | S96: İzin ve ruhsatlar; sayaç/fatura kayıtları; emisyon ve atık beyanları; proje/teknik raporlar; doğrulama ve sosyal koruma belgeleri. | T96: NACE kodu eşleştirmeyi destekler; tek başına taksonomi uyumluluğunu kanıtlamaz. | U96: Türkiye Yeşil Taksonomisi Yönetmeliği, EK-1
A97: 95 | B97: 10 | C97: Tarım Faaliyetleri | D97: A-10.1 | E97: Bitkisel ve Hayvansal Üretim | F97: EK-1 faaliyet başlığıdır. Ayrıntılı kapsam ve eşikler için yayımlanacak resmi teknik tarama kriterleri incelenmelidir. | H97: Diğer / Genel Faaliyet | I97: Hayır | J97: Hayır | K97: Evet | Q97: Yayımlanmamış / Doğrulanmalı | R97: Faaliyet hacmi; enerji, yakıt, su, atık ve sera gazı verileri; hasılat, CAPEX ve OPEX; teknik performans göstergeleri. | S97: İzin ve ruhsatlar; sayaç/fatura kayıtları; emisyon ve atık beyanları; proje/teknik raporlar; doğrulama ve sosyal koruma belgeleri. | T97: NACE kodu eşleştirmeyi destekler; tek başına taksonomi uyumluluğunu kanıtlamaz. | U97: Türkiye Yeşil Taksonomisi Yönetmeliği, EK-1
A98: 96 | B98: 11 | C98: Turizm Faaliyetleri | D98: A-11.1 | E98: Turizm, Gezi ve Turizm Konaklama Faaliyetleri | F98: EK-1 faaliyet başlığıdır. Ayrıntılı kapsam ve eşikler için yayımlanacak resmi teknik tarama kriterleri incelenmelidir. | H98: Diğer / Genel Faaliyet | I98: Hayır | J98: Hayır | K98: Evet | Q98: Yayımlanmamış / Doğrulanmalı | R98: Faaliyet hacmi; enerji, yakıt, su, atık ve sera gazı verileri; hasılat, CAPEX ve OPEX; teknik performans göstergeleri. | S98: İzin ve ruhsatlar; sayaç/fatura kayıtları; emisyon ve atık beyanları; proje/teknik raporlar; doğrulama ve sosyal koruma belgeleri. | T98: NACE kodu eşleştirmeyi destekler; tek başına taksonomi uyumluluğunu kanıtlamaz. | U98: Türkiye Yeşil Taksonomisi Yönetmeliği, EK-1
A99: 97 | B99: 6 | C99: Ulaştırma Faaliyetleri | D99: B-6.15 | E99: Karayolu Taşımacılığı ve Toplu Taşımaya Olanak Sağlayan Altyapı | F99: EK-1 faaliyet başlığıdır. Ayrıntılı kapsam ve eşikler için yayımlanacak resmi teknik tarama kriterleri incelenmelidir. | H99: Diğer / Genel Faaliyet | I99: Hayır | J99: Hayır | L99: Evet | Q99: Yayımlanmamış / Doğrulanmalı | R99: Faaliyet hacmi; enerji, yakıt, su, atık ve sera gazı verileri; hasılat, CAPEX ve OPEX; teknik performans göstergeleri. | S99: İzin ve ruhsatlar; sayaç/fatura kayıtları; emisyon ve atık beyanları; proje/teknik raporlar; doğrulama ve sosyal koruma belgeleri. | T99: NACE kodu eşleştirmeyi destekler; tek başına taksonomi uyumluluğunu kanıtlamaz. | U99: Türkiye Yeşil Taksonomisi Yönetmeliği, EK-1
A100: 98 | B100: 6 | C100: Ulaştırma Faaliyetleri | D100: B-6.16 | E100: Su Taşımacılığına Olanak Sağlayan Altyapı | F100: EK-1 faaliyet başlığıdır. Ayrıntılı kapsam ve eşikler için yayımlanacak resmi teknik tarama kriterleri incelenmelidir. | H100: Diğer / Genel Faaliyet | I100: Hayır | J100: Hayır | L100: Evet | Q100: Yayımlanmamış / Doğrulanmalı | R100: Faaliyet hacmi; enerji, yakıt, su, atık ve sera gazı verileri; hasılat, CAPEX ve OPEX; teknik performans göstergeleri. | S100: İzin ve ruhsatlar; sayaç/fatura kayıtları; emisyon ve atık beyanları; proje/teknik raporlar; doğrulama ve sosyal koruma belgeleri. | T100: NACE kodu eşleştirmeyi destekler; tek başına taksonomi uyumluluğunu kanıtlamaz. | U100: Türkiye Yeşil Taksonomisi Yönetmeliği, EK-1
A101: 99 | B101: 6 | C101: Ulaştırma Faaliyetleri | D101: B-6.17 | E101: Havalimanı Altyapısı | F101: EK-1 faaliyet başlığıdır. Ayrıntılı kapsam ve eşikler için yayımlanacak resmi teknik tarama kriterleri incelenmelidir. | H101: Diğer / Genel Faaliyet | I101: Hayır | J101: Hayır | L101: Evet | Q101: Yayımlanmamış / Doğrulanmalı | R101: Faaliyet hacmi; enerji, yakıt, su, atık ve sera gazı verileri; hasılat, CAPEX ve OPEX; teknik performans göstergeleri. | S101: İzin ve ruhsatlar; sayaç/fatura kayıtları; emisyon ve atık beyanları; proje/teknik raporlar; doğrulama ve sosyal koruma belgeleri. | T101: NACE kodu eşleştirmeyi destekler; tek başına taksonomi uyumluluğunu kanıtlamaz. | U101: Türkiye Yeşil Taksonomisi Yönetmeliği, EK-1
A102: 100 | B102: 8 | C102: Bilgi ve İletişim Faaliyetleri | D102: B-8.3 | E102: Bilgisayar Programlama, Danışmanlık ve İlgili Faaliyetler | F102: EK-1 faaliyet başlığıdır. Ayrıntılı kapsam ve eşikler için yayımlanacak resmi teknik tarama kriterleri incelenmelidir. | H102: Diğer / Genel Faaliyet | I102: Hayır | J102: Hayır | L102: Evet | Q102: Yayımlanmamış / Doğrulanmalı | R102: Faaliyet hacmi; enerji, yakıt, su, atık ve sera gazı verileri; hasılat, CAPEX ve OPEX; teknik performans göstergeleri. | S102: İzin ve ruhsatlar; sayaç/fatura kayıtları; emisyon ve atık beyanları; proje/teknik raporlar; doğrulama ve sosyal koruma belgeleri. | T102: NACE kodu eşleştirmeyi destekler; tek başına taksonomi uyumluluğunu kanıtlamaz. | U102: Türkiye Yeşil Taksonomisi Yönetmeliği, EK-1
A103: 101 | B103: 8 | C103: Bilgi ve İletişim Faaliyetleri | D103: B-8.4 | E103: Programlama ve Yayıncılık Faaliyetleri (Kolaylaştırıcı Faaliyet) | F103: EK-1 faaliyet başlığıdır. Ayrıntılı kapsam ve eşikler için yayımlanacak resmi teknik tarama kriterleri incelenmelidir. | H103: Kolaylaştırıcı Faaliyet | I103: Evet | J103: Hayır | L103: Evet | Q103: Yayımlanmamış / Doğrulanmalı | R103: Faaliyet hacmi; enerji, yakıt, su, atık ve sera gazı verileri; hasılat, CAPEX ve OPEX; teknik performans göstergeleri. | S103: İzin ve ruhsatlar; sayaç/fatura kayıtları; emisyon ve atık beyanları; proje/teknik raporlar; doğrulama ve sosyal koruma belgeleri. | T103: NACE kodu eşleştirmeyi destekler; tek başına taksonomi uyumluluğunu kanıtlamaz. | U103: Türkiye Yeşil Taksonomisi Yönetmeliği, EK-1
A104: 102 | B104: 9 | C104: Mesleki, Bilimsel ve Teknik Faaliyetler | D104: B-9.4 | E104: İklim Değişikliğine Uyum Sağlamaya Yönelik Mühendislik Faaliyetleri ve İlgili Teknik Danışmanlık | F104: EK-1 faaliyet başlığıdır. Ayrıntılı kapsam ve eşikler için yayımlanacak resmi teknik tarama kriterleri incelenmelidir. | H104: Kolaylaştırıcı Faaliyet | I104: Evet | J104: Hayır | L104: Evet | Q104: Yayımlanmamış / Doğrulanmalı | R104: Faaliyet hacmi; enerji, yakıt, su, atık ve sera gazı verileri; hasılat, CAPEX ve OPEX; teknik performans göstergeleri. | S104: İzin ve ruhsatlar; sayaç/fatura kayıtları; emisyon ve atık beyanları; proje/teknik raporlar; doğrulama ve sosyal koruma belgeleri. | T104: NACE kodu eşleştirmeyi destekler; tek başına taksonomi uyumluluğunu kanıtlamaz. | U104: Türkiye Yeşil Taksonomisi Yönetmeliği, EK-1
A105: 103 | B105: 12 | C105: Sanat, Eğlence ve Rekreasyon Faaliyetleri | D105: B-10.1 | E105: Kütüphaneler, Arşivler, Müzeler ve Kültürel Faaliyetler (Kolaylaştırıcı Faaliyet) | F105: EK-1 faaliyet başlığıdır. Ayrıntılı kapsam ve eşikler için yayımlanacak resmi teknik tarama kriterleri incelenmelidir. | H105: Kolaylaştırıcı Faaliyet | I105: Evet | J105: Hayır | L105: Evet | Q105: Yayımlanmamış / Doğrulanmalı | R105: Faaliyet hacmi; enerji, yakıt, su, atık ve sera gazı verileri; hasılat, CAPEX ve OPEX; teknik performans göstergeleri. | S105: İzin ve ruhsatlar; sayaç/fatura kayıtları; emisyon ve atık beyanları; proje/teknik raporlar; doğrulama ve sosyal koruma belgeleri. | T105: NACE kodu eşleştirmeyi destekler; tek başına taksonomi uyumluluğunu kanıtlamaz. | U105: Türkiye Yeşil Taksonomisi Yönetmeliği, EK-1
A106: 104 | B106: 13 | C106: Finans ve Sigorta Faaliyetleri | D106: B-11.1 | E106: Hayat Dışı Sigorta: İklimle İlgili Risklerin Sigortalanması (Kolaylaştırıcı Faaliyet) | F106: EK-1 faaliyet başlığıdır. Ayrıntılı kapsam ve eşikler için yayımlanacak resmi teknik tarama kriterleri incelenmelidir. | H106: Kolaylaştırıcı Faaliyet | I106: Evet | J106: Hayır | L106: Evet | Q106: Yayımlanmamış / Doğrulanmalı | R106: Faaliyet hacmi; enerji, yakıt, su, atık ve sera gazı verileri; hasılat, CAPEX ve OPEX; teknik performans göstergeleri. | S106: İzin ve ruhsatlar; sayaç/fatura kayıtları; emisyon ve atık beyanları; proje/teknik raporlar; doğrulama ve sosyal koruma belgeleri. | T106: NACE kodu eşleştirmeyi destekler; tek başına taksonomi uyumluluğunu kanıtlamaz. | U106: Türkiye Yeşil Taksonomisi Yönetmeliği, EK-1
...

Sheet 16 SEKTÖR
A1: 16 SEKTÖR | NİHAİ EK-1 ÖZETİ
A2: Sektör No | B2: Sektör Adı | C2: Ekonomik Faaliyet Sayısı | D2: Ana Çevresel Hedef | E2: İlgili Faaliyet Kodları | F2: Kolaylaştırıcı Faaliyet Var mı? | G2: Geçiş Faaliyeti Var mı? | H2: Açıklama | I2: Kaynak
A3: 1 | B3: Ormancılık Faaliyetleri | C3: =COUNTIF('137 EKONOMİK FAALİYET'!$C$3:$C$139,B3) | D3: Sera gazı emisyonlarının azaltımı | E3: A-1.1, B-1.1, A-1.2, B-1.2, A-1.3, B-1.3, A-1.4, B-1.4 | F3: Hayır | G3: Hayır | H3: Nihai EK-1 kapsamında yer alan faaliyetlerin benzersiz faaliyet bazında özeti. | I3: Türkiye Yeşil Taksonomisi Yönetmeliği, EK-1
A4: 2 | B4: Çevre Koruma ve Restorasyon Faaliyetleri | C4: =COUNTIF('137 EKONOMİK FAALİYET'!$C$3:$C$139,B4) | D4: Sera gazı emisyonlarının azaltımı | E4: A-2.1, B-2.1, E-1.1 | F4: Hayır | G4: Hayır | H4: Nihai EK-1 kapsamında yer alan faaliyetlerin benzersiz faaliyet bazında özeti. | I4: Türkiye Yeşil Taksonomisi Yönetmeliği, EK-1
A5: 3 | B5: İmalat Faaliyetleri | C5: =COUNTIF('137 EKONOMİK FAALİYET'!$C$3:$C$139,B5) | D5: Sera gazı emisyonlarının azaltımı | E5: A-3.1, B-3.1, A-3.2, B-3.2, A-3.3, B-3.3, A-3.4, B-3.4, A-3.5, B-3.5, A-3.6, B-3.6, A-3.7, B-3.7, A-3.8, B-3.8, A-3.9, B-3.9, A-3.10, B-3.10, A-3.11, B-3.11, A-3.12, B-3.12, A-3.13, B-3.13, A-3.14, B-3.14, A-3.15, B-3.15, A-3.16, B-3.16, A-3.17, B-3.17, C-1.1, Ç-1.1, Ç-1.2, D-1.1, D-1.2 | F5: Evet | G5: Evet | H5: Nihai EK-1 kapsamında yer alan faaliyetlerin benzersiz faaliyet bazında özeti. | I5: Türkiye Yeşil Taksonomisi Yönetmeliği, EK-1
A6: 4 | B6: Enerji Faaliyetleri | C6: =COUNTIF('137 EKONOMİK FAALİYET'!$C$3:$C$139,B6) | D6: Sera gazı emisyonlarının azaltımı | E6: A-4.1, B-4.1, A-4.2, B-4.2, A-4.3, B-4.3, A-4.4, B-4.4, A-4.5, B-4.5, A-4.6, B-4.6, A-4.7, B-4.7, A-4.8, B-4.8, A-4.9, B-4.9, A-4.10, B-4.10, A-4.11, B-4.11, A-4.12, B-4.12, A-4.13, B-4.13, A-4.14, B-4.14, A-4.15, B-4.15, A-4.16, B-4.16, A-4.17, B-4.17, A-4.18, B-4.18, A-4.19, B-4.19, A-4.20, B-4.20, A-4.21, B-4.21, A-4.22, B-4.22, A-4.23, B-4.23, A-4.24, B-4.24, A-4.25, B-4.25, A-4.26, B-4.26, A-4.27, B-4.27, A-4.28, B-4.28, A-4.29, B-4.29, A-4.30, B-4.30, A-4.31, B-4.31 | F6: Evet | G6: Evet | H6: Nihai EK-1 kapsamında yer alan faaliyetlerin benzersiz faaliyet bazında özeti. | I6: Türkiye Yeşil Taksonomisi Yönetmeliği, EK-1
A7: 5 | B7: Su Temini, Kanalizasyon, Atık Yönetimi ve İyileştirme Faaliyetleri | C7: =COUNTIF('137 EKONOMİK FAALİYET'!$C$3:$C$139,B7) | D7: Sera gazı emisyonlarının azaltımı | E7: A-5.1, B-5.1, A-5.2, B-5.2, A-5.3, B-5.3, A-5.4, B-5.4, A-5.5, B-5.5, A-5.6, B-5.6, A-5.7, B-5.7, A-5.8, B-5.8, A-5.9, B-5.9, A-5.10, B-5.10, A-5.11, B-5.11, A-5.12, B-5.12, C-2.1, C-2.2, C-2.3, Ç-2.1, Ç-2.2, Ç-2.3, Ç-2.4, D-2.2, Ç-2.5, Ç-2.6, Ç-2.7, D-2.1, D-2.3, D-2.4 | F7: Evet | G7: Hayır | H7: Nihai EK-1 kapsamında yer alan faaliyetlerin benzersiz faaliyet bazında özeti. | I7: Türkiye Yeşil Taksonomisi Yönetmeliği, EK-1
A8: 6 | B8: Ulaştırma Faaliyetleri | C8: =COUNTIF('137 EKONOMİK FAALİYET'!$C$3:$C$139,B8) | D8: Sera gazı emisyonlarının azaltımı | E8: A-6.1, B-6.1, A-6.2, B-6.2, A-6.3, B-6.3, A-6.4, B-6.4, A-6.5, B-6.5, A-6.6, B-6.6, A-6.7, B-6.7, A-6.8, B-6.8, A-6.9, B-6.9, A-6.10, B-6.10, A-6.11, B-6.11, A-6.12, B-6.12, A-6.13, B-6.13, A-6.14, B-6.14, A-6.15, A-6.16, A-6.17, B-6.15, B-6.16, B-6.17 | F8: Evet | G8: Evet | H8: Nihai EK-1 kapsamında yer alan faaliyetlerin benzersiz faaliyet bazında özeti. | I8: Türkiye Yeşil Taksonomisi Yönetmeliği, EK-1
A9: 7 | B9: İnşaat ve Emlak Faaliyetleri | C9: =COUNTIF('137 EKONOMİK FAALİYET'!$C$3:$C$139,B9) | D9: Sera gazı emisyonlarının azaltımı | E9: A-7.1, B-7.1, Ç-3.1, A-7.2, B-7.2, Ç-3.2, A-7.3, B-7.3, A-7.4, B-7.4, A-7.5, B-7.5, A-7.6, B-7.6, A-7.7, B-7.7, Ç-3.3, Ç-3.4, Ç-3.5 | F9: Evet | G9: Evet | H9: Nihai EK-1 kapsamında yer alan faaliyetlerin benzersiz faaliyet bazında özeti. | I9: Türkiye Yeşil Taksonomisi Yönetmeliği, EK-1
A10: 8 | B10: Bilgi ve İletişim Faaliyetleri | C10: =COUNTIF('137 EKONOMİK FAALİYET'!$C$3:$C$139,B10) | D10: İklim değişikliğine uyum | E10: A-8.1, B-8.1, A-8.2, B-8.2, B-8.3, B-8.4, C-4.1, Ç-4.1 | F10: Evet | G10: Evet | H10: Nihai EK-1 kapsamında yer alan faaliyetlerin benzersiz faaliyet bazında özeti. | I10: Türkiye Yeşil Taksonomisi Yönetmeliği, EK-1
A11: 9 | B11: Mesleki, Bilimsel ve Teknik Faaliyetler | C11: =COUNTIF('137 EKONOMİK FAALİYET'!$C$3:$C$139,B11) | D11: İklim değişikliğine uyum | E11: A-9.1, B-9.1, A-9.2, B-9.2, A-9.3, B-9.3, B-9.4 | F11: Evet | G11: Hayır | H11: Nihai EK-1 kapsamında yer alan faaliyetlerin benzersiz faaliyet bazında özeti. | I11: Türkiye Yeşil Taksonomisi Yönetmeliği, EK-1
A12: 10 | B12: Tarım Faaliyetleri | C12: =COUNTIF('137 EKONOMİK FAALİYET'!$C$3:$C$139,B12) | D12: Sera gazı emisyonlarının azaltımı | E12: A-10.1 | F12: Hayır | G12: Hayır | H12: Nihai EK-1 kapsamında yer alan faaliyetlerin benzersiz faaliyet bazında özeti. | I12: Türkiye Yeşil Taksonomisi Yönetmeliği, EK-1
A13: 11 | B13: Turizm Faaliyetleri | C13: =COUNTIF('137 EKONOMİK FAALİYET'!$C$3:$C$139,B13) | D13: Sera gazı emisyonlarının azaltımı | E13: A-11.1 | F13: Hayır | G13: Hayır | H13: Nihai EK-1 kapsamında yer alan faaliyetlerin benzersiz faaliyet bazında özeti. | I13: Türkiye Yeşil Taksonomisi Yönetmeliği, EK-1
A14: 12 | B14: Sanat, Eğlence ve Rekreasyon Faaliyetleri | C14: =COUNTIF('137 EKONOMİK FAALİYET'!$C$3:$C$139,B14) | D14: İklim değişikliğine uyum | E14: B-10.1 | F14: Evet | G14: Hayır | H14: Nihai EK-1 kapsamında yer alan faaliyetlerin benzersiz faaliyet bazında özeti. | I14: Türkiye Yeşil Taksonomisi Yönetmeliği, EK-1
... A18: 16 | B18: Konaklama Faaliyetleri | C18: =COUNTIF('137 EKONOMİK FAALİYET'!$C$3:$C$139,B18) | D18: Biyoçeşitliliğin ve ekosistemlerin korunması ile restorasyonu | E18: E-2.1 | F18: Hayır | G18: Hayır | H18: Nihai EK-1 kapsamında yer alan faaliyetlerin benzersiz faaliyet bazında özeti. | I18: Türkiye Yeşil Taksonomisi Yönetmeliği, EK-1
A21: TOPLAM SEKTÖR: | B21: =COUNTA(B3:B18)
A22: TOPLAM EKONOMİK FAALİYET: | B22: =SUM(C3:C18)

Sheet 6 ÇEVRESEL HEDEF
A1: TÜRKİYE YEŞİL TAKSONOMİSİ | 6 ÇEVRESEL HEDEF
A2: Hedef No | B2: Hedef Adı | C2: Kısa Açıklama | D2: Şirket Açısından Örnek Veri | E2: Muhtemel Kanıt | F2: İlgili Faaliyetler
A3: 1 | B3: Sera gazı emisyonlarının azaltımı | C3: Sera gazı emisyonlarının azaltılması ile yutak alanların korunması, artırılması ve iyileştirilmesi. | D3: Enerji/yakıt, emisyon, su, atık, malzeme, dayanıklılık veya biyoçeşitlilik göstergeleri. | E3: Sayaç, fatura, analiz, izin, proje, izleme ve doğrulama kayıtları. | F3: 96 faaliyet
A4: 2 | B4: İklim değişikliğine uyum | C4: İklim değişikliğinin mevcut veya olası olumsuz etkilerine karşı dayanıklılık ve uyum. | D4: Enerji/yakıt, emisyon, su, atık, malzeme, dayanıklılık veya biyoçeşitlilik göstergeleri. | E4: Sayaç, fatura, analiz, izin, proje, izleme ve doğrulama kayıtları. | F4: 100 faaliyet
A5: 3 | B5: Su ve deniz kaynaklarının sürdürülebilir kullanımı ve korunması | C5: Su ve deniz kaynaklarının durumunun iyileştirilmesi, korunması ve kirlenmenin önlenmesi. | D5: Enerji/yakıt, emisyon, su, atık, malzeme, dayanıklılık veya biyoçeşitlilik göstergeleri. | E5: Sayaç, fatura, analiz, izin, proje, izleme ve doğrulama kayıtları. | F5: 6 faaliyet
A6: 4 | B6: Döngüsel ekonomiye geçiş | C6: Kaynakların daha uzun süre kullanılması, yeniden kullanım, onarım ve geri/ileri dönüşüm. | D6: Enerji/yakıt, emisyon, su, atık, malzeme, dayanıklılık veya biyoçeşitlilik göstergeleri. | E6: Sayaç, fatura, analiz, izin, proje, izleme ve doğrulama kayıtları. | F6: 21 faaliyet
A7: 5 | B7: Kirliliğin önlenmesi ve kontrolü | C7: Hava, su, toprak, koku, gürültü kirliliği ve atık oluşumunun önlenmesi ve kontrolü. | D7: Enerji/yakıt, emisyon, su, atık, malzeme, dayanıklılık veya biyoçeşitlilik göstergeleri. | E7: Sayaç, fatura, analiz, izin, proje, izleme ve doğrulama kayıtları. | F7: 6 faaliyet
A8: 6 | B8: Biyoçeşitliliğin ve ekosistemlerin korunması ile restorasyonu | C8: Doğal yaşam alanlarının, türlerin ve ekosistemlerin korunması ve restorasyonu. | D8: Enerji/yakıt, emisyon, su, atık, malzeme, dayanıklılık veya biyoçeşitlilik göstergeleri. | E8: Sayaç, fatura, analiz, izin, proje, izleme ve doğrulama kayıtları. | F8: 2 faaliyet

Sheet ŞİRKETİMİ KONTROL ET
A1: ŞİRKETİMİ KONTROL ET | GİRİŞ VE ÖN DEĞERLENDİRME
A3: Şirket Adı | F3: NACE kodu eşleştirmeyi destekleyen bir referanstır; tek başına taksonomi uyumluluğunu kanıtlamaz.
A4: Sektör
A5: Ana Faaliyet
A6: İkincil Faaliyet | F6: A — EK-1 KAPSAMI
A7: NACE Kodu | F7: =IF(B5="","EŞLEŞTİRME GEREKLİ",IF(COUNTIF('137 EKONOMİK FAALİYET'!$E$3:$E$139,B5)>0,"EVET","EŞLEŞTİRME GEREKLİ"))
A8: İl
A9: Tesis / Lokasyon | F9: B — TEKNİK KRİTER DURUMU
A10: Yıllık Ciro | F10: =IF(B5="","VERİ YETERSİZ","YAYIMLANMAMIŞ / DOĞRULANMALI")
A11: Yıllık CAPEX
A12: Yıllık OPEX | F12: C — TAKSONOMİ UYUM DURUMU
A13: Yıllık Elektrik Tüketimi | F13: =IF(B5="","Henüz doğrulanmadı",IF(COUNTIF(B18:B22,"Veri Yok")>0,"Veri eksik","Teknik kriter incelemesi gerekli"))
A14: Yıllık Yakıt Tüketimi
A15: Yıllık Su Tüketimi
A16: Yıllık Atık Miktarı | F16: ÜÇ TEMEL UYUM ŞARTI
A17: Yıllık Sera Gazı Emisyonu
A18: Mevcut GES | F18: Önemli Katkı | G18: En az bir hedefe önemli katkı? | H18: İncelenmedi
A19: Mevcut BESS | F19: DNSH | G19: Diğer hedeflere önemli zarar vermeme? | H19: İncelenmedi
A20: Enerji Verimliliği Projesi | F20: Asgari Sosyal Koruma | G20: Sosyal koruma şartları? | H20: İncelenmedi
A21: Karbon Ayak İzi Hesabı
A22: TSRS Raporlaması | F22: Bu üç alan otomatik olarak “uyumlu” sonucuna bağlanmaz. Kesin sonuç için yayımlanmış teknik kriterler ve doğrulanabilir kanıtlar değerlendirilmelidir.
A23: Mevcut Sertifikalar
A24: Diğer Çevresel Veriler

Sheet _LISTELER
A1: Ormancılık Faaliyetleri | B1: Ağaçlandırma
A2: Çevre Koruma ve Restorasyon Faaliyetleri | B2: Yeniden Ağaçlandırma, Doğal Orman Yenilenmesi, Ormanların Rehabilitasyonu ve Restorasyonu
A3: İmalat Faaliyetleri | B3: Orman Yönetimi
A4: Enerji Faaliyetleri | B4: Koruma Ormancılığı
A5: Su Temini, Kanalizasyon, Atık Yönetimi ve İyileştirme Faaliyetleri | B5: Sulak Alanların Restorasyonu
A6: Ulaştırma Faaliyetleri | B6: Yenilenebilir Enerji Teknolojilerinin İmalatı (Kolaylaştırıcı Faaliyet)
A7: İnşaat ve Emlak Faaliyetleri | B7: Hidrojen İmalatı ve Kullanımına Yönelik Ekipmanların İmalatı (Kolaylaştırıcı Faaliyet)
A8: Bilgi ve İletişim Faaliyetleri | B8: Taşımacılık İçin Düşük Karbon Teknolojilerinin İmalatı (Kolaylaştırıcı Faaliyet)
A9: Mesleki, Bilimsel ve Teknik Faaliyetler | B9: Batarya İmalatı (Kolaylaştırıcı Faaliyet)
A10: Tarım Faaliyetleri | B10: Binalar İçin Enerji Verimliliği Ekipmanlarının İmalatı (Kolaylaştırıcı Faaliyet)
A11: Turizm Faaliyetleri | B11: Diğer Düşük Karbon Teknolojilerinin İmalatı (Kolaylaştırıcı Faaliyet)
A12: Sanat, Eğlence ve Rekreasyon Faaliyetleri | B12: Çimento İmalatı
... A16: Konaklama Faaliyetleri | B16: Karbon Siyahı İmalatı
B17: Soda Külü İmalatı
B18: Klor İmalatı
B19: Organik Temel Kimyasalların İmalatı
B20: Susuz Amonyak İmalatı
B21: Nitrik Asit İmalatı
B22: Birincil Formdaki Plastiklerin İmalatı
B23: Fotovoltaik Teknolojisi Kullanılarak Elektrik Üretimi
B24: Yoğunlaştırılmış Güneş Enerjisi (CSP) Teknolojisi Kullanılarak Elektrik Üretimi
B25: Rüzgâr Enerjisinden Elektrik Üretimi
B26: Dalga Enerjisi Teknolojilerinden Elektrik Üretimi
B27: Hidroelektrik Enerjiden Elektrik Üretimi
B28: Jeotermal Enerjiden Elektrik Üretimi
... B137: Oteller, Tatil, Kamp Alanları ve Benzeri Konaklama Yerleri

Sheet HAZIRLIK CHECKLIST
A1: ŞİRKET HAZIRLIK KONTROL LİSTESİ
A2: No | B2: Kontrol Maddesi | C2: Durum | D2: Not
A3: 1 | B3: Faaliyet eşleştirmesi yapıldı | C3: Eksik
A4: 2 | B4: İlgili EK-1 faaliyeti belirlendi | C4: Eksik
A5: 3 | B5: NACE kodu kontrol edildi | C5: Eksik
A6: 4 | B6: Enerji tüketim verileri hazır | C6: Eksik
A7: 5 | B7: Yakıt tüketim verileri hazır | C7: Eksik
A8: 6 | B8: Sera gazı emisyon verileri hazır | C8: Eksik
A9: 7 | B9: Scope 1 verileri hazır | C9: Eksik
A10: 8 | B10: Scope 2 verileri hazır | C10: Eksik
A11: 9 | B11: Su tüketim verileri hazır | C11: Eksik
A12: 10 | B12: Atık verileri hazır | C12: Eksik
A13: 11 | B13: Çevresel izinler kontrol edildi | C13: Eksik
A14: 12 | B14: Enerji verimliliği verileri hazır | C14: Eksik
... A23: 21 | B23: Teknik tarama kriterleri kontrol edildi | C23: Eksik

Sheet KANIT BELGE ENVANTERİ
A1: KANIT / BELGE ENVANTERİ
A2: Belge / Veri | B2: Neden Gerekli? | C2: İlgili Faaliyet | D2: İlgili Çevresel Hedef | E2: Mevcut mu? | F2: Dosya / Referans | G2: Sorumlu Birim | H2: Son Güncelleme | I2: Eksik / Tam | J2: Not
E3: Hayır | I3: Eksik
E4: Hayır | I4: Eksik
E5: Hayır | I5: Eksik
E6: Hayır | I6: Eksik
E7: Hayır | I7: Eksik
E8: Hayır | I8: Eksik
E9: Hayır | I9: Eksik
E10: Hayır | I10: Eksik
E11: Hayır | I11: Eksik
E12: Hayır | I12: Eksik
E13: Hayır | I13: Eksik
E14: Hayır | I14: Eksik
... E32: Hayır | I32: Eksik

Sheet FAALİYET EŞLEŞTİRME
A1: FAALİYET EŞLEŞTİRME | ARAMA VE REFERANS
A3: Sektör seç
A4: Faaliyet seç
A5: NACE kodu ara
A6: Anahtar kelime ara
A9: NACE kodu eşleştirmeyi destekleyen bir referanstır; tek başına taksonomi uyumluluğunu kanıtlamaz. Şirketin fiilen yürüttüğü ekonomik faaliyet esas alınmalıdır. Dinamik filtreleme için ana veri tablosundaki filtreleri veya Excel’in Arama özelliğini kullanın.
A14: Seçilen faaliyet | B14: =B4
A15: EK-1 kapsamı | B15: =IF(B4="","EŞLEŞTİRME GEREKLİ",IF(COUNTIF('137 EKONOMİK FAALİYET'!$E$3:$E$139,B4)>0,"EVET","HAYIR"))
A16: Sonuç | B16: =IF(B15="EVET","Teknik kriter incelemesi gerekli","Henüz doğrulanmadı")

Sheet RAPORLAMA TAKVİMİ
A1: TÜRKİYE YEŞİL TAKSONOMİSİ TAKVİMİ
A2: Tarih | B2: Kapsam | C2: Durum | D2: Açıklama | E2: Kaynak
A3: 24.09.2026 | B3: Yönetmelik | C3: Yayımlandı / yürürlükte | D3: Yönetmelik yayımı tarihinde yürürlüğe girdi. | E3: https://www.resmigazete.gov.tr/eskiler/2026/09/20260924-1.htm
A4: 24.09.2026 | B4: Reel sektör | C4: Gönüllü raporlama | D4: EK-1 faaliyetini yürüten kurum, kuruluş ve işletmeler resmi şablonlara göre raporlama yapabilir. Finansal kuruluşlar şirketlerden raporlama talep edebilir. | E4: https://www.resmigazete.gov.tr/eskiler/2026/09/20260924-1.htm
A5: 01.01.2029 | B5: Finansal kuruluşlar | C5: Zorunlu raporlama dönemi | D5: Geçiş hükmü uyarınca finansal kuruluşlar bu tarihe kadar raporlama yapmak zorunda değildir. | E5: https://www.resmigazete.gov.tr/eskiler/2026/09/20260924-1.htm

Sheet KAYNAKLAR
A1: RESMİ KAYNAKLAR
A2: No | B2: Kaynak | C2: Bağlantı | D2: Kullanım Notu
A3: 1 | B3: Türkiye Yeşil Taksonomisi Yönetmeliği | C3: https://www.resmigazete.gov.tr/eskiler/2026/09/20260924-1.htm | D3: Nihai hukuki metin ve yürürlük/raporlama hükümleri.
A4: 2 | B4: 24 Eylül 2026 tarihli ve 33380 sayılı Resmî Gazete | C4: https://www.resmigazete.gov.tr/eskiler/2026/09/20260924-1.htm | D4: Yönetmeliğin resmi yayımı.
A5: 3 | B5: Türkiye Yeşil Taksonomisi Yönetmeliği, EK-1 | C5: https://www.resmigazete.gov.tr/eskiler/2026/09/20260924-1-1.pdf | D5: 16 sektör ve 137 benzersiz ekonomik faaliyetin kaynağı.
A6: 4 | B6: İklim Değişikliği Başkanlığı | C6: https://iklim.gov.tr/turkiye-yesil-taksonomisi-yonetmeligi-yayimlandi-haber-6008 | D6: Resmi duyuru; 16 sektör, 137 faaliyet ve raporlama özeti.
A7: 5 | B7: Teknik tarama kriterleri | C7: https://iklim.gov.tr/ | D7: Yönetmelik md.11 uyarınca Başkanlığın resmi internet sayfasında yayımlanır; dosya hazırlanırken nihai kriter bağlantısı tespit edilemedi.
A10: TASLAK / NİHAİ METİN AYRIMI Bu çalışma yalnızca 24.09.2026 tarihli nihai Yönetmelik ve nihai EK-1 esas alınarak hazırlanmıştır. 2024 ve öncesi taslaklardaki NACE kodları, tanımlar ve teknik eşikler nihai bilgi olarak aktarılmamıştır. Nihai teknik tarama kriterleri yayımlandığında veri alanları resmi belgeye göre güncellenmelidir.

Sheet KALİTE KONTROL
A1: KALİTE KONTROL
A2: Kontrol | B2: Sonuç | C2: Beklenen | D2: Durum
A3: Sektör sayısı | B3: =COUNTA('16 SEKTÖR'!B3:B18) | C3: 16 | D3: =IF(B3=C3,"TAMAM",IF(OR(ISTEXT(B3),ISTEXT(C3)),"KONTROL EDİLDİ","HATA"))
A4: Faaliyet sayısı | B4: =COUNTA('137 EKONOMİK FAALİYET'!E3:E139) | C4: 137 | D4: =IF(B4=C4,"TAMAM",IF(OR(ISTEXT(B4),ISTEXT(C4)),"KONTROL EDİLDİ","HATA"))
A5: Benzersiz faaliyet satırı | B5: Programatik üretim ve benzersiz sektör+faaliyet anahtarı | C5: 137 | D5: =IF(B5=C5,"TAMAM",IF(OR(ISTEXT(B5),ISTEXT(C5)),"KONTROL EDİLDİ","HATA"))
A6: Çevresel hedef sayısı | B6: =COUNTA('6 ÇEVRESEL HEDEF'!B3:B8) | C6: 6 | D6: =IF(B6=C6,"TAMAM",IF(OR(ISTEXT(B6),ISTEXT(C6)),"KONTROL EDİLDİ","HATA"))
A7: Teknik kriter kesin uyum sonucu | B7: Hiçbir formül kesin “uyumlu/uyumsuz” sonucu üretmez | C7: Evet | D7: =IF(B7=C7,"TAMAM",IF(OR(ISTEXT(B7),ISTEXT(C7)),"KONTROL EDİLDİ","HATA"))
A8: Taslak NACE aktarımı | B8: Taslak NACE kodları aktarılmadı | C8: Evet | D8: =IF(B8=C8,"TAMAM",IF(OR(ISTEXT(B8),ISTEXT(C8)),"KONTROL EDİLDİ","HATA"))
A9: Nihai EK-1 kaynağı | B9: Her faaliyet satırında kaynak bulunur | C9: Evet | D9: =IF(B9=C9,"TAMAM",IF(OR(ISTEXT(B9),ISTEXT(C9)),"KONTROL EDİLDİ","HATA"))
